{% set sqrt2=sqrt(2.0) %}
{% set leg_thickness=0.08 %}

{% set default_leg_length=0.2 %}
{% set default_aux_length=0.2 %}
{% set default_foot_length=0.4 %}

{% if set_mode == "all" %}
    {% set fl_leg_length=size[0] %}
    {% set fl_aux_length=size[1] %}
    {% set fl_foot_length=size[2] %}
    {% set fr_leg_length=size[3] %}
    {% set fr_aux_length=size[4] %}
    {% set fr_foot_length=size[5] %}
    {% set bl_leg_length=size[6] %}
    {% set bl_aux_length=size[7] %}
    {% set bl_foot_length=size[8] %}
    {% set br_leg_length=size[9] %}
    {% set br_aux_length=size[10] %}
    {% set br_foot_length=size[11] %}
{% elif set_mode == "same" %}
    {% set fl_leg_length=size[0] %}
    {% set fl_aux_length=size[1] %}
    {% set fl_foot_length=size[2] %}
    {% set fr_leg_length=size[0] %}
    {% set fr_aux_length=size[1] %}
    {% set fr_foot_length=size[2] %}
    {% set bl_leg_length=size[0] %}
    {% set bl_aux_length=size[1] %}
    {% set bl_foot_length=size[2] %}
    {% set br_leg_length=size[0] %}
    {% set br_aux_length=size[1] %}
    {% set br_foot_length=size[2] %}
{% elif set_mode == "same_only_back" %}
    {% set fl_leg_length=default_leg_length %}
    {% set fl_aux_length=default_aux_length %}
    {% set fl_foot_length=default_foot_length %}
    {% set fr_leg_length=default_leg_length %}
    {% set fr_aux_length=default_aux_length %}
    {% set fr_foot_length=default_foot_length %}
    {% set bl_leg_length=size[0] %}
    {% set bl_aux_length=size[1] %}
    {% set bl_foot_length=size[2] %}
    {% set br_leg_length=size[0] %}
    {% set br_aux_length=size[1] %}
    {% set br_foot_length=size[2] %}
{% elif set_mode == "same_only_front" %}
    {% set fl_leg_length=size[0] %}
    {% set fl_aux_length=size[1] %}
    {% set fl_foot_length=size[2] %}
    {% set fr_leg_length=size[0] %}
    {% set fr_aux_length=size[1] %}
    {% set fr_foot_length=size[2] %}
    {% set bl_leg_length=default_leg_length %}
    {% set bl_aux_length=default_aux_length %}
    {% set bl_foot_length=default_foot_length %}
    {% set br_leg_length=default_leg_length %}
    {% set br_aux_length=default_aux_length %}
    {% set br_foot_length=default_foot_length %}
{% elif set_mode == "none" %}
    {% set fl_leg_length=default_leg_length %}
    {% set fl_aux_length=default_aux_length %}
    {% set fl_foot_length=default_foot_length %}
    {% set fr_leg_length=default_leg_length %}
    {% set fr_aux_length=default_aux_length %}
    {% set fr_foot_length=default_foot_length %}
    {% set bl_leg_length=default_leg_length %}
    {% set bl_aux_length=default_aux_length %}
    {% set bl_foot_length=default_foot_length %}
    {% set br_leg_length=default_leg_length %}
    {% set br_aux_length=default_aux_length %}
    {% set br_foot_length=default_foot_length %}
{% endif %}


<mujoco model="ant">
  <compiler angle="degree" coordinate="local" inertiafromgeom="true"/>

  <!-- <option integrator="RK4" timestep="0.01"/> -->
  <option integrator="RK4" timestep="0.01">
    <flag warmstart="disable" />
  </option>

  <custom>
    <numeric data="0.0 0.0 0.55 1.0 0.0 0.0 0.0 0.0 1.0 0.0 -1.0 0.0 -1.0 0.0 1.0" name="init_qpos"/>
  </custom>
  <default>
    <joint armature="1" damping="1" limited="true"/>
    <geom conaffinity="0" condim="3" density="5.0" friction="1 0.5 0.5" margin="0.01" rgba="0.8 0.6 0.4 1"/>
  </default>
  <asset>
    <texture builtin="gradient" height="100" rgb1="1 1 1" rgb2="0 0 0" type="skybox" width="100"/>
    <texture builtin="flat" height="1278" mark="cross" markrgb="1 1 1" name="texgeom" random="0.01" rgb1="0.8 0.6 0.4" rgb2="0.8 0.6 0.4" type="cube" width="127"/>
    <texture builtin="checker" height="100" name="texplane" rgb1="0 0 0" rgb2="0.8 0.8 0.8" type="2d" width="100"/>
    <material name="MatPlane" reflectance="0.5" shininess="1" specular="1" texrepeat="60 60" texture="texplane"/>
    <material name="geom" texture="texgeom" texuniform="true"/>
    <material name="red" rgba="0.847 0.066 0.349 1"/>
    <material name="blue" rgba="0.047 0.166 0.949 1"/>
    <material name="yellow" rgba="0.947 0.966 0.149 1"/>
    <material name="green" rgba="0.047 0.966 0.349 1"/>
    <material name="pink" rgba="0.947 0.066 0.999 1"/>
  </asset>
  <worldbody>
    <light cutoff="100" diffuse="1 1 1" dir="-0 0 -1.3" directional="true" exponent="1" pos="0 0 1.3" specular=".1 .1 .1"/>
    <geom conaffinity="1" condim="3" material="MatPlane" name="floor" pos="0 0 0" rgba="0.8 0.9 0.8 1" size="40 40 40" type="plane"/>
    <body name="torso" pos="0 0 0.75">
      <camera name="track" mode="trackcom" pos="0 -3 0.3" xyaxes="1 0 0 0 0 1"/>
      <geom name="torso_geom" pos="0 0 0" size="0.25" type="sphere"/>
      <joint armature="0" damping="0" limited="false" margin="0.01" name="root" pos="0 0 0" type="free"/>
      <site name="torso_track" pos="0.0 0.0 0.0" size="0.02" material="red" />
      <site name="fltorso_track" pos="0.0 0.0 0.0" size="0.02" material="yellow" />
      <site name="frtorso_track" pos="0.0 0.0 0.0" size="0.02" material="yellow" />
      <site name="brtorso_track" pos="0.0 0.0 0.0" size="0.02" material="yellow" />
      <site name="bltorso_track" pos="0.0 0.0 0.0" size="0.02" material="yellow" />
      <body name="front_left_leg" pos="0 0 0">
          <geom fromto="0.0 0.0 0.0 {{ fl_leg_length }} {{ fl_leg_length }} 0.0" name="aux_1_geom" size="{{ leg_thickness }}" type="capsule"/>
          <site name="flleg_track" pos="{{ fl_leg_length }} {{ fl_leg_length }} 0.0" size="0.02" material="blue" />
        <body name="aux_1" pos="{{ fl_leg_length }} {{ fl_leg_length }} 0">
          <joint axis="0 0 1" name="hip_1" pos="0.0 0.0 0.0" range="-30 30" type="hinge"/>
          <geom fromto="0.0 0.0 0.0 {{ fl_aux_length }} {{ fl_aux_length }} 0.0" name="left_leg_geom" size="{{ leg_thickness }}" type="capsule"/>
          <site name="flaux_track" pos="{{ fl_aux_length }} {{ fl_aux_length }} 0.0" size="0.02" material="pink" />
          <body pos="{{ fl_aux_length }} {{ fl_aux_length }} 0">
            <joint axis="-1 1 0" name="ankle_1" pos="0.0 0.0 0.0" range="30 70" type="hinge"/>
            <geom fromto="0.0 0.0 0.0 {{ fl_foot_length }} {{ fl_foot_length }} 0.0" name="left_ankle_geom" size="{{ leg_thickness }}" type="capsule"/>
            <site name="flfoot_track" pos="{{ fl_foot_length + leg_thickness*sqrt2/2}} {{ fl_foot_length + leg_thickness*sqrt2/2}} 0.0" size="0.02" material="green" />
          </body>
        </body>
      </body>
      <body name="front_right_leg" pos="0 0 0">
          <geom fromto="0.0 0.0 0.0 -{{ fr_leg_length }} {{ fr_leg_length }} 0.0" name="aux_2_geom" size="{{ leg_thickness }}" type="capsule"/>
          <site name="frleg_track" pos="-{{ fr_leg_length }} {{ fr_leg_length }} 0.0" size="0.02" material="blue" />
        <body name="aux_2" pos="-{{ fr_leg_length }} {{ fr_leg_length }} 0">
          <joint axis="0 0 1" name="hip_2" pos="0.0 0.0 0.0" range="-30 30" type="hinge"/>
          <geom fromto="0.0 0.0 0.0 -{{ fr_aux_length }} {{ fr_aux_length }} 0.0" name="right_leg_geom" size="{{ leg_thickness }}" type="capsule"/>
          <site name="fraux_track" pos="-{{ fr_aux_length }} {{ fr_aux_length }} 0.0" size="0.02" material="pink" />
          <body pos="-{{ fr_aux_length }} {{ fr_aux_length }} 0">
            <joint axis="1 1 0" name="ankle_2" pos="0.0 0.0 0.0" range="-70 -30" type="hinge"/>
            <geom fromto="0.0 0.0 0.0 -{{ fr_foot_length }} {{ fr_foot_length }} 0.0" name="right_ankle_geom" size="{{ leg_thickness }}" type="capsule"/>
            <site name="frfoot_track" pos="-{{ fr_foot_length + leg_thickness*sqrt2/2}} {{ fr_foot_length + leg_thickness*sqrt2/2}} 0.0" size="0.02" material="green" />
          </body>
        </body>
      </body>
      <body name="back_leg" pos="0 0 0">
          <geom fromto="0.0 0.0 0.0 -{{ bl_leg_length }} -{{ bl_leg_length }} 0.0" name="aux_3_geom" size="{{ leg_thickness }}" type="capsule"/>
          <site name="blleg_track" pos="-{{ bl_leg_length }} -{{ bl_leg_length }} 0.0" size="0.02" material="blue" />
        <body name="aux_3" pos="-{{ bl_leg_length }} -{{ bl_leg_length }} 0">
          <joint axis="0 0 1" name="hip_3" pos="0.0 0.0 0.0" range="-30 30" type="hinge"/>
          <geom fromto="0.0 0.0 0.0 -{{ bl_aux_length }} -{{ bl_aux_length }} 0.0" name="back_leg_geom" size="{{ leg_thickness }}" type="capsule"/>
          <site name="blaux_track" pos="-{{ bl_aux_length }} -{{ bl_aux_length }} 0.0" size="0.02" material="pink" />
          <body pos="-{{ bl_aux_length }} -{{ bl_aux_length }} 0">
            <joint axis="-1 1 0" name="ankle_3" pos="0.0 0.0 0.0" range="-70 -30" type="hinge"/>
            <geom fromto="0.0 0.0 0.0 -{{ bl_foot_length }} -{{ bl_foot_length }} 0.0" name="third_ankle_geom" size="{{ leg_thickness }}" type="capsule"/>
            <site name="blfoot_track" pos="-{{ bl_foot_length + leg_thickness*sqrt2/2}} -{{ bl_foot_length + leg_thickness*sqrt2/2}} 0.0" size="0.02" material="green" />
          </body>
        </body>
      </body>
      <body name="right_back_leg" pos="0 0 0">
          <geom fromto="0.0 0.0 0.0 {{ br_leg_length }} -{{ br_leg_length }} 0.0" name="aux_4_geom" size="{{ leg_thickness }}" type="capsule"/>
          <site name="brleg_track" pos="{{ br_leg_length }} -{{ br_leg_length }} 0.0" size="0.02" material="blue" />
        <body name="aux_4" pos="{{ br_leg_length }} -{{ br_leg_length }} 0">
          <joint axis="0 0 1" name="hip_4" pos="0.0 0.0 0.0" range="-30 30" type="hinge"/>
          <geom fromto="0.0 0.0 0.0 {{ br_aux_length }} -{{ br_aux_length }} 0.0" name="rightback_leg_geom" size="{{ leg_thickness }}" type="capsule"/>
          <site name="braux_track" pos="{{ br_aux_length }} -{{ br_aux_length }} 0.0" size="0.02" material="pink" />
          <body pos="{{ br_aux_length }} -{{ br_aux_length }} 0">
            <joint axis="1 1 0" name="ankle_4" pos="0.0 0.0 0.0" range="30 70" type="hinge"/>
            <geom fromto="0.0 0.0 0.0 {{ br_foot_length }} -{{ br_foot_length }} 0.0" name="fourth_ankle_geom" size="{{ leg_thickness }}" type="capsule"/>
            <site name="brfoot_track" pos="{{ br_foot_length + leg_thickness*sqrt2/2}} -{{ br_foot_length + leg_thickness*sqrt2/2}} 0.0" size="0.02" material="green" />
          </body>
        </body>
      </body>
    </body>
  </worldbody>
  <actuator>
    <motor ctrllimited="true" ctrlrange="-1.0 1.0" joint="hip_4" gear="150"/>
    <motor ctrllimited="true" ctrlrange="-1.0 1.0" joint="ankle_4" gear="150"/>
    <motor ctrllimited="true" ctrlrange="-1.0 1.0" joint="hip_1" gear="150"/>
    <motor ctrllimited="true" ctrlrange="-1.0 1.0" joint="ankle_1" gear="150"/>
    <motor ctrllimited="true" ctrlrange="-1.0 1.0" joint="hip_2" gear="150"/>
    <motor ctrllimited="true" ctrlrange="-1.0 1.0" joint="ankle_2" gear="150"/>
    <motor ctrllimited="true" ctrlrange="-1.0 1.0" joint="hip_3" gear="150"/>
    <motor ctrllimited="true" ctrlrange="-1.0 1.0" joint="ankle_3" gear="150"/>
  </actuator>
</mujoco>
